<?xml version="1.0" encoding="utf-8"?>
<!-- =================================================================================== -->
<!-- |    This document was autogenerated by xacro from crawler.xacro                  | -->
<!-- |    EDITING THIS FILE BY HAND IS NOT RECOMMENDED                                 | -->
<!-- =================================================================================== -->
<robot name="crawler">
  <!--Color Properties-->
  <material name="blue">
    <color rgba="0 0 0.8 1"/>
  </material>
  <material name="black">
    <color rgba="0 0 0 1"/>
  </material>
  <material name="white">
    <color rgba="1 1 1 1"/>
  </material>
  <material name="red">
    <color rgba="0.8 0.0 0.0 1.0"/>
  </material>
  <!-- Base Footprint -->
  <link name="base_footprint">
    <origin rpy="0 0 0" xyz="0 0 0"/>
    <!--xacro:box_inertia m="0.01" w="0.001" h="0.001" d="0.001"/-->
  </link>
  <!--Base link for the main body-->
  <link name="base_link">
    <origin rpy="0 0 0" xyz="0 0 0"/>
    <inertial>
      <mass value="0.01"/>
      <inertia ixx="9.375e-05" ixy="0.0" ixz="0.0" iyy="0.000131083333333" iyz="0.0" izz="4.33333333333e-05"/>
    </inertial>
    <collision>
      <geometry>
        <box size="0.22 0.33 0.06"/>
      </geometry>
    </collision>
  </link>
  <!--base_link to base_footprint Joint-->
  <joint name="base_link_joint" type="fixed">
    <origin rpy="0 0 0" xyz="0 0 0.0425"/>
    <parent link="base_footprint"/>
    <child link="base_link"/>
  </joint>

  <link name="left_front_wheel">
    <collision>
      <origin rpy="1.5707963268 0 0" xyz="0 0 0"/>
      <geometry>
        <cylinder length="0.055" radius="0.025"/>
      </geometry>
    </collision>
    <visual>
      <origin rpy="1.5707963268 0 0" xyz="0 0 0"/>
      <geometry>
        <cylinder length="0.055" radius="0.025"/>
      </geometry>
    </visual>
    <surface>
      <friction>
        <ode>
          <mu>100.0</mu>
          <mu2>100.0</mu2>
        </ode>
      </friction>
    </surface>
    <inertial>
      <mass value="0.5"/>
      <inertia ixx="0.000204166666667" ixy="0" ixz="0" iyy="0.000204166666667" iyz="0" izz="0.00015625"/>
    </inertial>
  </link>
  <joint name="left_front_wheel_joint" type="continuous">
    <axis rpy="0 0 0" xyz="0 1 0"/>
    <parent link="base_link"/>
    <child link="left_front_wheel"/>
    <origin rpy="0 0 0" xyz="0.0 0.07 -0.03"/>
  </joint>
  <link name="right_front_wheel">
    <collision>
      <origin rpy="1.5707963268 0 0" xyz="0 0 0"/>
      <geometry>
        <cylinder length="0.055" radius="0.025"/>
      </geometry>
    </collision>
    <visual>
      <origin rpy="1.5707963268 0 0" xyz="0 0 0"/>
      <geometry>
        <cylinder length="0.055" radius="0.025"/>
      </geometry>
    </visual>
    <surface>
      <friction>
        <ode>
          <mu>100.0</mu>
          <mu2>100.0</mu2>
        </ode>
      </friction>
    </surface>
    <inertial>
      <mass value="0.5"/>
      <inertia ixx="0.000204166666667" ixy="0" ixz="0" iyy="0.000204166666667" iyz="0" izz="0.00015625"/>
    </inertial>
  </link>
  <joint name="right_front_wheel_joint" type="continuous">
    <axis rpy="0 0 0" xyz="0 1 0"/>
    <parent link="base_link"/>
    <child link="right_front_wheel"/>
    <origin rpy="0 0 0" xyz="0.0 -0.07 -0.03"/>
  </joint>
 
  <!-- SPHERICAL CASTER WHEEL -->
  <!--Caster Wheel Link-->
  <link name="caster_wheel">
    <visual>
      <origin xyz="0 0 0" rpy="0 0 0"/>
      <geometry>
        <sphere radius="0.02"/>
      </geometry>
      <material name="white"/>
    </visual>
    <collision>
      <origin xyz="0 0 0" rpy="0 0 0"/>
      <geometry>
        <sphere radius="0.02"/>
      </geometry>
    </collision>
    <surface>
      <friction>
        <ode>
          <mu>100.0</mu>
          <mu2>100.0</mu2>
        </ode>
      </friction>
    </surface>
    <inertial>
      <mass value="0.25"/>
      <inertia ixx="0.00004" ixy="0.0" ixz="0.0" iyy="0.00004" iyz="0.0" izz="0.00004"/>
    </inertial>
  </link>

  <!--Caster Wheel Joint-->
  <joint name="caster_wheel_joint" type="continuous">
    <axis xyz="0 1 0" rpy="0 0 0"/>
    <parent link="base_link"/>
    <child link="caster_wheel"/>
    <origin xyz="-0.088 0.0 -0.0325" rpy="0 0 0"/>
  </joint>

</robot>

