<?xml version="1.0" ?>
<!-- =================================================================================== -->
<!-- |    This document was autogenerated by xacro from crawler.xacro                  | -->
<!-- |    EDITING THIS FILE BY HAND IS NOT RECOMMENDED                                 | -->
<!-- =================================================================================== -->
<robot name="crawler">
  <!-- Base Footprint -->
  <link name="base_footprint">
    <origin rpy="0 0 0" xyz="0 0 0"/>
  </link>
  <!--Base link for the main body-->
  <link name="base_link">
    <origin rpy="0 0 0" xyz="0 0 0"/>
    <inertial>
      <mass value="2"/>
      <inertia ixx="0.008333" ixy="0.0" ixz="0.0" iyy="0.008333" iyz="0.0" izz="0.0133333"/>
    </inertial>
    <collision>
      <geometry>
        <box size="0.2 0.2 0.05"/>
      </geometry>
    </collision>
  </link>
  <!--base_link to base_footprint Joint-->
  <joint name="base_link_joint" type="fixed">
    <origin rpy="0 0 0" xyz="0 0 0.0425"/>
    <parent link="base_footprint"/>
    <child link="base_link"/>
  </joint>
  <link name="left_front_wheel">
    <collision>
      <origin rpy="1.570796326795 0 0" xyz="0 0 0"/>
      <geometry>
        <!-- <mesh filename="./crawler_front_wheel_filet.stl" /> -->
        <cylinder length="0.055" radius="0.025"/>
      </geometry>
    </collision>
    <visual>
      <origin rpy="1.570796326795 0 0" xyz="0 0 0"/>
        <geometry>
	        <!-- <mesh filename="./crawler_front_wheel_filet.stl"/>	 -->
          <cylinder length="0.055" radius="0.025"/>
      </geometry>
    </visual>
    <surface>
      <friction>
        <ode>
          <mu>1.0</mu>
          <mu2>1.0</mu2>
        </ode>
      </friction>
    </surface>
    <inertial>
      <mass value="0.8"/>
      <inertia ixx="0.0003266666666666667" ixy="0" ixz="0" iyy="0.0003266666666666667" iyz="0" izz="0.00025000000000000006"/>
    </inertial>
  </link>
  <joint name="left_front_wheel_joint" type="continuous">
    <axis rpy="0 0 0" xyz="0 1 0"/>
    <parent link="base_link"/>
    <child link="left_front_wheel"/>
    <origin rpy="0 0 0" xyz="0.0 0.07 -0.03"/>
  </joint>
  <link name="right_front_wheel">
    <collision>
      <origin rpy="1.570796326795 0 0" xyz="0 0 0"/>
      <geometry>
        <!-- <mesh filename="./crawler_front_wheel_filet.stl" /> -->
        <cylinder length="0.055" radius="0.025"/>
      </geometry>
    </collision>
    <visual>
      <origin rpy="1.570796326795 0 0" xyz="0 0 0"/>
      <geometry>
        <!-- <mesh filename="./crawler_front_wheel_filet.stl" /> -->
        <cylinder length="0.055" radius="0.025"/>
      </geometry>
    </visual>
    <surface>
      <friction>
        <ode>
          <mu>1.0</mu>
          <mu2>1.0</mu2>
        </ode>
      </friction>
    </surface>
    <inertial>
      <mass value="0.8"/>
      <inertia ixx="0.0003266666666666667" ixy="0" ixz="0" iyy="0.0003266666666666667" iyz="0" izz="0.00025000000000000006"/>
    </inertial>
  </link>
  <joint name="right_front_wheel_joint" type="continuous">
    <axis rpy="0 0 0" xyz="0 1 0"/>
    <parent link="base_link"/>
    <child link="right_front_wheel"/>
    <origin rpy="0 0 0" xyz="0.0 -0.07 -0.03"/>
  </joint>
  <!--Caster Wheel Joint-->
  <joint name="caster_wheel_base_joint" type="continuous">
    <axis rpy="0 0 0" xyz="0 0 1"/>
    <parent link="base_link"/>
    <child link="caster_wheel_base"/>
    <origin rpy="0 0 0" xyz="-0.13 0.0 0"/>
  </joint>
  <!--Caster Wheel Link-->
  <link name="caster_wheel_base">
    <origin rpy="0 0 0" xyz="0.0 0.0 0.0"/>
    <visual>
      <origin rpy="0 0 0" xyz="0.065 0 0"/>
      <geometry>
        <box size="0.13 0.01 0.01"/>
      </geometry>
    </visual>
    <inertial>
      <mass value="0.2"/>
      <inertia ixx="3.3333333333333334e-08" ixy="0.0" ixz="0.0" iyy="3.3333333333333334e-08" iyz="0.0" izz="3.3333333333333334e-08"/>
    </inertial>
  </link>
  <joint name="caster_wheel_joint" type="continuous">
    <axis rpy="0 0 0" xyz="0 1 0"/>
    <parent link="caster_wheel_base"/>
    <child link="caster_wheel"/>
    <origin rpy="0 0 0" xyz="-0.02 0 -0.035"/>
  </joint>
  <link name="caster_wheel">
    <collision>
      <origin rpy="1.570796326795 0 0" xyz="0 0 0"/>
      <geometry>
        <!-- <mesh filename="./crawler_caster_wheel_filet.stl" /> -->
        <cylinder length="0.04" radius="0.02"/>
      </geometry>
    </collision>
    <visual>
      <origin rpy="1.570796326795 0 0" xyz="0 0 0"/>
      <geometry>
        <!-- <mesh filename="./crawler_caster_wheel_filet.stl" /> -->
        <cylinder length="0.04" radius="0.02"/>
      </geometry>
    </visual>
    <surface>
      <friction>
        <ode>
          <mu>1.0</mu>
          <mu2>1.0</mu2>
        </ode>
      </friction>
    </surface>
    <inertial>
      <mass value="0.5"/>
      <inertia ixx="0.00011666666666666667" ixy="0" ixz="0" iyy="0.00011666666666666667" iyz="0" izz="0.0001"/>
    </inertial>
  </link>
</robot>
